thread_ID, Id, ParentId, PostType, Score, CreationDate, OwnerID, Body
45263405,45263405,null,1,1,Sun Jul 23 09:08:00 EDT 2017,8352534,"<p>I am using AWSIoTPythonSDKÂ pahoâ€?mqtt library and have problem connecting to AWS. Please help. Thanks! </p>		<pre><code>#coding: utf-8		from AWSIoTPythonSDK.MQTTLib import AWSIoTMQTTClient	from datetime import datetime	from time import sleep	from gpiozero import Buzzer, LED		bz = Buzzer(22)	led = LED(18)		#Â CustomÂ MQTTÂ messageÂ callbackÂ 	def custom_callback (client,userdata,message):	    print("ReceivedÂ aÂ newÂ message:Â ")	    print(message.payload)		    if message.payload == 'button_pressed':	        print("Doorbell pressed")	        bz.on()	        led.blink()	        sleep(1)	        bz.off()	        led.off()	        print("Done")		host="xxxxxxx.iot.ap-southeast-1.amazonaws.com"	rootCAPath="rootca.pem"	certificatePath="certificate.pem.crt"	privateKeyPath="private.pem.key"	my_rpi=AWSIoTMQTTClient("basicPubSub")	my_rpi.configureEndpoint(host,8883)	my_rpi.configureCredentials(rootCAPath,privateKeyPath,certificatePath)	my_rpi.configureOfflinePublishQueueing(-1)#Â InfiniteÂ offlineÂ PublishÂ queueing	my_rpi.configureDrainingFrequency(2)#Â Draining:Â 2Â Hz	my_rpi.configureConnectDisconnectTimeout(10)#Â 10Â sec	my_rpi.configureMQTTOperationTimeout(5)#Â 5Â sec	#Â ConnectÂ andÂ subscribeÂ toÂ AWSÂ IoTÂ 	my_rpi.connect()	my_rpi.subscribe("sensors/button",1,custom_callback)		sleep(2)	</code></pre>		<p>This is the errors I received when I run the above code. I have checked that I have installed the necessary library. All AWS certs and keys are stored in the same folder as the above python code.</p>		<pre><code>Traceback (most recent call last):	  File "Doorbell_Indoor.py", line 38, in &lt;module&gt;	    my_rpi.connect()	  File "/usr/local/lib/python2.7/dist-packages/AWSIoTPythonSDK/MQTTLib.py", line 403, in connect	    return self._mqttCore.connect(keepAliveIntervalSecond)	  File "/usr/local/lib/python2.7/dist-packages/AWSIoTPythonSDK/core/protocol/mqttCore.py", line 290, in connect	    self._pahoClient.connect(self._host, self._port, keepAliveInterval)  # Throw exception...	  File "/usr/local/lib/python2.7/dist-packages/AWSIoTPythonSDK/core/protocol/paho/client.py", line 655, in connect	    return self.reconnect()	  File "/usr/local/lib/python2.7/dist-packages/AWSIoTPythonSDK/core/protocol/paho/client.py", line 777, in reconnect	    sock = socket.create_connection((self._host, self._port), source_address=(self._bind_address, 0))	  File "/usr/lib/python2.7/socket.py", line 553, in create_connection	    for res in getaddrinfo(host, port, 0, SOCK_STREAM):	socket.gaierror: [Errno -2] Name or service not known	</code></pre>	"
